Workbook
Name f.b: Calculation!$W$260
Name M.b: Calculation!$W$253
Name M.d: Calculation!#REF!
Name M.g: Calculation!#REF!
Name M.LL: Calculation!$W$259
Name M.LT: Calculation!#REF!
Name M.ws: Calculation!$W$254
Name S.b: Calculation!#REF!
Name Table_f.pe.service.L: INDEX(Calculation!$R$380:$R$434,1):INDEX(Calculation!$R$380:$R$434,COUNT(Calculation!$R$380:$R$434))
Name Table_f.pu.service.lim: INDEX(Calculation!$V$380:$V$434,1):INDEX(Calculation!$V$380:$V$434,COUNT(Calculation!$V$380:$V$434))
Name Table_L: INDEX(Calculation!$F$380:$F$434,1):INDEX(Calculation!$F$380:$F$434,COUNT(Calculation!$F$380:$F$434))
Name Table_Location: Calculation!$F$380:INDEX(Calculation!$I$382:$I$434, MATCH(TRUE, Calculation!$I$382:$I$434="", 0) - 1)
Name Table_SLS: Calculation!$R$380:INDEX(Calculation!$N$382:$N$434, MATCH(TRUE, Calculation!$N$382:$N$434="", 0) - 1)
Name Table_SLS_D_C: Calculation!$Z$380:INDEX(Calculation!$X$382:$X$434, MATCH(TRUE, Calculation!$X$382:$X$434="", 0) - 1)
Name TEMPLATE_VERSION: Inputs!$D$22

Sheet Guidance and Scope

Sheet Inputs
A1: Project Name | B1: North Connector Bridge | I1: Location Along Span (m) | L1: PT Eccentricity, e (m) | O1: DC (kN m) | R1: DW (kN m) | U1: LL+IM (kN m)
A2: Jacobs Project Number | B2: 408545
A3: Section | B3: C.1
A4: Originator | B4: TG
A5: Date | B5: 46305 | I5: 0 | L5: =40*0.0254 -> 1.016 | O5: =1*1.356 -> 1.356 | R5: =1308*1.356 -> 1773.648 | U5: =9559*1.356 -> 12962.004
A6: Checker | B6: SB | I6: =1*0.3048 -> 0.3048 | L6: =39*0.0254 -> 0.9906 | O6: =100*1.356 -> 135.6 | R6: =$O6+$R$5 -> 1909.248 | U6: =$O6+$U$5 -> 13097.604
A7: Date | B7: 46091 | I7: =2*0.3048 -> 0.6096 | L7: =38*0.0254 -> 0.9652 | O7: =200*1.356 -> 271.2 | R7: =$O7+$R$5 -> 2044.848 | U7: =$O7+$U$5 -> 13233.204
A8: Revision No. | B8: 1 | I8: =3*0.3048 -> 0.9144 | L8: =37*0.0254 -> 0.9398 | O8: =300*1.356 -> 406.8 | R8: =$O8+$R$5 -> 2180.448 | U8: =$O8+$U$5 -> 13368.804
I9: =4*0.3048 -> 1.2192 | L9: =36*0.0254 -> 0.9144 | O9: =400*1.356 -> 542.4 | R9: =$O9+$R$5 -> 2316.048 | U9: =$O9+$U$5 -> 13504.404
A10: Post-Tensioning Tensile Strength, fpu = | B10: =270*6.89475729 -> 1861.5845 | I10: =5*0.3048 -> 1.524 | L10: =35*0.0254 -> 0.889 | O10: =800*1.356 -> 1084.8 | R10: =$O10+$R$5 -> 2858.448 | U10: =$O10+$U$5 -> 14046.804
A11: Post-Tensioning Yield Strength, fpy = | B11: =243*6.89475729 -> 1675.426 | I11: =6*0.3048 -> 1.8288 | L11: =34*0.0254 -> 0.8636 | O11: =1200*1.356 -> 1627.2 | R11: =$O11+$R$5 -> 3400.848 | U11: =$O11+$U$5 -> 14589.204
A12: Moment of Interia of the entire superstructure section, I = | B12: =6596207*0.0000004162 -> 2.7453414 | I12: =7*0.3048 -> 2.1336 | L12: =33*0.0254 -> 0.8382 | O12: =1500*1.356 -> 2034 | R12: =$O12+$R$5 -> 3807.648 | U12: =$O12+$U$5 -> 14996.004
A13: Post-Tensioning Steel Modulus of Elasticity, Eps = | B13: =28500*6.89475729 -> 196500.58 | I13: =8*0.3048 -> 2.4384 | L13: =32*0.0254 -> 0.8128 | O13: =2000*1.356 -> 2712 | R13: =$O13+$R$5 -> 4485.648 | U13: =$O13+$U$5 -> 15674.004
A14: Modulus of Elasticity of concrete, Ec = | B14: =3861*6.89475729 -> 26620.658 | I14: =9*0.3048 -> 2.7432 | L14: =31*0.0254 -> 0.7874 | O14: =3000*1.356 -> 4068 | R14: =$O14+$R$5 -> 5841.648 | U14: =$O14+$U$5 -> 17030.004
A15: Effective Post-Tensioning Stress at Jacking End, fpe.jack = | B15: =188.37819*6.89475729 -> 1298.8219 | I15: =10*0.3048 -> 3.048 | L15: =30*0.0254 -> 0.762 | O15: =4000*1.356 -> 5424 | R15: =$O15+$R$5 -> 7197.648 | U15: =$O15+$U$5 -> 18386.004
A16: Effective Post-Tensioning Stress at Midspan, fpe.mid = | B16: =193.9707*6.89475729 -> 1337.3809 | I16: =11*0.3048 -> 3.3528 | L16: =29*0.0254 -> 0.7366 | O16: =6000*1.356 -> 8136 | R16: =$O16+$R$5 -> 9909.648 | U16: =$O16+$U$5 -> 21098.004
A17: Effective Post-Tensioning Stress at End of Seating Zone, fpe.seat = | B17: =198.1287*6.89475729 -> 1366.0493 | I17: =12*0.3048 -> 3.6576 | L17: =28*0.0254 -> 0.7112 | O17: =8000*1.356 -> 10848 | R17: =$O17+$R$5 -> 12621.648 | U17: =$O17+$U$5 -> 23810.004
A18: Effective Post-Tensioning Stress at Non-Jacking End, fpe.njack = | B18: =176.40315*6.89475729 -> 1216.2569 | I18: =13*0.3048 -> 3.9624 | L18: =27*0.0254 -> 0.6858 | O18: =10000*1.356 -> 13560 | R18: =$O18+$R$5 -> 15333.648 | U18: =$O18+$U$5 -> 26522.004
A19: Effective Post-Tensioning Stress at Service Limit State, fpe.service = | B19: =169.91667*6.89475729 -> 1171.5342 | I19: =14*0.3048 -> 4.2672 | L19: =26*0.0254 -> 0.6604 | O19: =12000*1.356 -> 16272 | R19: =$O19+$R$5 -> 18045.648 | U19: =$O19+$U$5 -> 29234.004
A20: Tendon Type = | B20: Low Relaxation Strand | I20: =15*0.3048 -> 4.572 | L20: =25*0.0254 -> 0.635 | O20: =14000*1.356 -> 18984 | R20: =$O20+$R$5 -> 20757.648 | U20: =$O20+$U$5 -> 31946.004
I21: =16*0.3048 -> 4.8768 | L21: =24*0.0254 -> 0.6096 | O21: =15044*1.356 -> 20399.664 | R21: =$O21+$R$5 -> 22173.312 | U21: =$O21+$U$5 -> 33361.668
A22: TEMPLATE_VERSION | D22: 1.0.0 | I22: =17*0.3048 -> 5.1816 | L22: =25*0.0254 -> 0.635 | O22: =14000*1.356 -> 18984 | R22: =$R$21-O6 -> 22037.712 | U22: =$U$21-R6 -> 31452.42
I23: =18*0.3048 -> 5.4864 | L23: =26*0.0254 -> 0.6604 | O23: =12000*1.356 -> 16272 | R23: =$R$21-O7 -> 21902.112 | U23: =$U$21-R7 -> 31316.82
I24: =19*0.3048 -> 5.7912 | L24: =27*0.0254 -> 0.6858 | O24: =10000*1.356 -> 13560 | R24: =$R$21-O8 -> 21766.512 | U24: =$U$21-R8 -> 31181.22
I25: =20*0.3048 -> 6.096 | L25: =28*0.0254 -> 0.7112 | O25: =8000*1.356 -> 10848 | R25: =$R$21-O9 -> 21630.912 | U25: =$U$21-R9 -> 31045.62
I26: =21*0.3048 -> 6.4008 | L26: =29*0.0254 -> 0.7366 | O26: =6000*1.356 -> 8136 | R26: =$R$21-O10 -> 21088.512 | U26: =$U$21-R10 -> 30503.22
I27: =22*0.3048 -> 6.7056 | L27: =30*0.0254 -> 0.762 | O27: =4000*1.356 -> 5424 | R27: =$R$21-O11 -> 20546.112 | U27: =$U$21-R11 -> 29960.82
I28: =23*0.3048 -> 7.0104 | L28: =31*0.0254 -> 0.7874 | O28: =3000*1.356 -> 4068 | R28: =$R$21-O12 -> 20139.312 | U28: =$U$21-R12 -> 29554.02
I29: =24*0.3048 -> 7.3152 | L29: =32*0.0254 -> 0.8128 | O29: =2000*1.356 -> 2712 | R29: =$R$21-O13 -> 19461.312 | U29: =$U$21-R13 -> 28876.02
I30: =25*0.3048 -> 7.62 | L30: =33*0.0254 -> 0.8382 | O30: =1500*1.356 -> 2034 | R30: =$R$21-O14 -> 18105.312 | U30: =$U$21-R14 -> 27520.02
I31: =26*0.3048 -> 7.9248 | L31: =34*0.0254 -> 0.8636 | O31: =1200*1.356 -> 1627.2 | R31: =$R$21-O15 -> 16749.312 | U31: =$U$21-R15 -> 26164.02
I32: =27*0.3048 -> 8.2296 | L32: =35*0.0254 -> 0.889 | O32: =800*1.356 -> 1084.8 | R32: =$R$21-O16 -> 14037.312 | U32: =$U$21-R16 -> 23452.02
I33: =28*0.3048 -> 8.5344 | L33: =36*0.0254 -> 0.9144 | O33: =400*1.356 -> 542.4 | R33: =$R$21-O17 -> 11325.312 | U33: =$U$21-R17 -> 20740.02
I34: =29*0.3048 -> 8.8392 | L34: =37*0.0254 -> 0.9398 | O34: =300*1.356 -> 406.8 | R34: =$R$21-O18 -> 8613.312 | U34: =$U$21-R18 -> 18028.02
I35: =30*0.3048 -> 9.144 | L35: =38*0.0254 -> 0.9652 | O35: =200*1.356 -> 271.2 | R35: =$R$21-O19 -> 5901.312 | U35: =$U$21-R19 -> 15316.02
I36: =31*0.3048 -> 9.4488 | L36: =39*0.0254 -> 0.9906 | O36: =100*1.356 -> 135.6 | R36: =$R$21-O20 -> 3189.312 | U36: =$U$21-R20 -> 12604.02
I37: =32*0.3048 -> 9.7536 | L37: =40*0.0254 -> 1.016 | O37: =1*1.356 -> 1.356 | R37: =$R$21-O21 -> 1773.648 | U37: =$U$21-R21 -> 11188.356

Sheet Calculation
Q1: COMPUTATION SHEET | AD1: Page:
AD2: Originator: | AH2: =Inputs!B4 -> TG
AD3: Date: | AH3: =Inputs!B5 -> 46305
A4: Project Name: | E4: =Inputs!B1 -> North Connector Bridge | AD4: Checker: | AH4: =Inputs!B6 -> SB
A5: Project No.: | E5: =Inputs!B2 -> 408545 | AD5: Date: | AH5: =Inputs!B7 -> 46091
A6: Section: | E6: =Inputs!B3&" Strand Stresses" -> C.1 Strand Stresses | AD6: Revision No.: | AH6: =Inputs!B8 -> 1
A8: =Inputs!B3&" Strand Stress Checks" -> C.1 Strand Stress Checks
AE9: Equation or Reference
C10: 1 | E10: Introduction
E12: This section evaluates prestressing strand stresses at applicable construction and service stages in accordance with AASHTO LRFD requirements. Strand stresses are checked at critical locations along the member using the section properties, strand geometry, and prestress force assumptions defined herein to verify compliance with allowable stress limits.
C17: 1.1 | G17: Design Philosophy for Post‑Tensioning Strand Stress Checks
G19: The design of post‑tensioned concrete members requires explicit verification that prestressing strand stresses remain within allowable limits at all critical stages of construction and service. Unlike conventional reinforcing steel, prestressing strand is intentionally stressed to a high fraction of its tensile strength, making strand stress limits a controlling design consideration. AASHTO LRFD adopts a staged design philosophy in which allowable prestressing strand stresses vary depending on construction sequence, loss mechanisms, and bonded behavior. Accordingly, strand stresses must be evaluated at multiple discrete stages—including jacking, anchorage seating, post‑seating, and long‑term service—each of which is subject to different governing limits. The calculations presented herein follow this philosophy and explicitly evaluate strand stresses at each required stage.
C31: 1.2 | G31: Staged Nature of Prestressing Strand Stress Limits
G33: Prestressing strand stress limits prescribed by AASHTO LRFD are stage‑dependent, reflecting both the physical behavior of prestressing systems and observed performance of tendons in service. Maximum allowable stresses vary based on whether the strand is unbonded or bonded, whether anchorage seating has occurred, and whether time‑dependent losses and superimposed loads have developed. It is important to recognize that the maximum strand stress does not necessarily occur under service loading, nor does it necessarily occur at the jacking end. In many cases, the governing stress occurs immediately after anchorage seating at or near the end of the seating loss zone. The design approach implemented in this tool reflects this behavior by explicitly checking all applicable stages rather than relying on a single controlling condition.
C52: 1.3 | G52: Stress–Strain Characteristics of Prestressing Strand
G54: The AASHTO LRFD Commentary emphasizes caution in the selection of jacking stresses due to the sensitivity of prestressing steel to overstress, especially prior to long‑term loss development. While the Specification provides upper bounds on allowable stresses, the Commentary notes that practical limits are often governed by anchorage behavior, friction variability, and field tolerances. Additionally, it should be noted that prestressing strand does not exhibit a distinct yield point in the same manner of mild reinforcing steel. For design purposes, AASHTO therefore defines a nominal yield strength, fy, for prestressing steel as a specified fraction of the ultimate tensile strength, fu. Allowable prestressing stresses are then expressed either directly as fractions of fu​ or indirectly as fractions of fy​, depending on the construction stage being evaluated. This convention provides a consistent basis for establishing stress limits despite the absence of a true material yield plateau.
C67: 1.4 | G67: Bonded Behavior and Strain Compatibility Assumptions
G69: Following grouting, post‑tensioning tendons are assumed to be fully bonded to the surrounding concrete. Under bonded conditions, changes in tendon stress due to applied loads are calculated using strain compatibility, whereby the tendon strain is assumed equal to the concrete strain at the tendon elevation. Accordingly, stresses in the prestressing strand due to dead load, wearing surface, and live load with dynamic allowance are calculated based on elastic section behavior. These stress increments are then combined algebraically with the effective prestress after losses to obtain the total strand stress for service‑level evaluations. This assumption is valid for service stress checks where the section remains uncracked and prestressing forces dominate section behavior.
C80: 1.5 | G80: Intended Use and Limitations
G82: This tool is intended for use in the design and verification of bonded post‑tensioned concrete bridge members designed in accordance with AASHTO LRFD. It assumes elastic section behavior for stress‑limit evaluations and relies on prestress loss values obtained from analytical software. The tool is not intended to replace detailed nonlinear analysis, tendon stressing procedures, or construction‑stage modeling where such analyses is warranted. Engineering judgment remains essential in the selection of jacking force, interpretation of stress results, and evaluation of unusual geometries or construction sequences.
C96: 2 | E96: Design Equations and Nomenclature
E98: The nomenclature and equations used throughout this calculation tool are described in this section.
C101: 2.1. | G101: Description of Variables
G104: e = | H104: variation of strand eccentricity along the girder (m)
G105: Ec = | H105: modulus of elasticity of concrete (MPa)
G106: Eps = | H106: modulus of elasticity of post-tensioning steel (MPa)
G107: fpe.jack = | H107: effective post-tensioning stress at jacking end (MPa)
G108: fpe.mid = | H108: effective post-tensioning stress at midspan (MPa)
G109: fpe.njack = | H109: effective post-tensioning stress at non-jacking end (MPa)
G110: fpe.seat = | H110: effective post-tensioning stress at end of seating zone (MPa)
G111: fpe.service = | H111: effective post-tensioning stress at servicel Limit state (MPa)
G112: fpe.service.L = | H112: variation of effective post-tensioning stress in service limit state along the girder (MPa)
G113: fpe.service.L1 = | H113: effective post-tensioning stress at end of span in service limit state (MPa)
G114: fpe.service.L2 = | H114: effective post-tensioning stress at start of span in service limit state (MPa)
G115: fpe.service.L3= | H115: effective post-tensioning stress at midspan in service limit state (MPa)
... G123: Mu = | H123: sum of moments due to DC, DW, and LL + IM (kN m)
C140: 3 | E140: Section Properties
E142: This subsection summarizes the geometric, material, and prestressing parameters used in the strand stress limit calculations. The properties listed below define the section configuration, reinforcing layout, duct geometry, and material characteristics required to evaluate strand stresses in accordance with AASHTO LRFD provisions.
C147: 3.1. | G147: Geometry and Materials
V150: Post-Tensioning Tensile Strength, fpu = | W150: =Inputs!B10 -> 1861.5845
...

Sheet Outputs
A1: Allowable Stresses in strands at critical locations:
A3: =Calculation!I228 -> Stress Prior to Anchorage Seating
A4: =Calculation!V238 -> Eff. Post-Tensioning Stress at Jacking End, fpe.jack = | B4: =Calculation!W238 -> 1298.8219
A5: =Calculation!V239 -> Stress Limit Prior to Anchorage Seating, fps.jack.lim = | B5: =Calculation!W239 -> 1507.8834
A6: =Calculation!V240 -> Stress Limit Prior to Seating DC Ratio, DC = | B6: =Calculation!W240 -> 0.86135432
A8: =[1]Calculation!I234 -> 0
A9: =Calculation!V255 -> Eff. Post-Tensioning Stress at Jacking End, fpe.jack = | B9: =Calculation!W255 -> 1298.8219
A10: =Calculation!V256 -> Stress Limit Immediately After Anchorage Set, fpu.jack.lim = | B10: =Calculation!W256 -> 1303.1091
A11: =Calculation!V257 -> Stress Limit Immediately After Anchorage Set DC Ratio, DC = | B11: =Calculation!W257 -> 0.99671
A13: =Calculation!V259 -> Eff. Post-Tensioning Stress at Non-Jacking End, fpe.njack = | B13: =Calculation!W259 -> 1216.2569
A14: =Calculation!V260 -> Stress Limit Immediately After Anchorage Set, fpu.jack.lim = | B14: =Calculation!W260 -> 1303.1091
A15: =Calculation!V261 -> Stress Limit Immediately After Anchorage Set DC Ratio, DC = | B15: =Calculation!W261 -> 0.93335
A17: =Calculation!I272 -> Stress Prior to Anchorage Seating
A18: =Calculation!V288 -> Eff. Post-Tensioning Stress at End Seating, fpe.seat = | B18: =Calculation!W288 -> 1366.0493
A19: =Calculation!V289 -> Stress Limit Prior to Anchorage Seating, fpu.seat.lim = | B19: =Calculation!W289 -> 1377.5725
A20: =Calculation!V290 -> Stress Limit Prior to Anchorage Seating DC Ratio, DC = | B20: =Calculation!W290 -> 0.99163514
A22: =[1]Calculation!I276 -> 0
A23: =Calculation!V335 -> Eff. Post-Tensioning Stress at End of Span in Service, fpe.service.L1 = | B23: =Calculation!W335 -> 1211.7922
A24: =Calculation!V336 -> Stress Limit Prior to Anchorage Seating in Service, fpu.service.lim = | B24: =Calculation!W336 -> 1340.3408
A25: =Calculation!V337 -> Stress Limit Prior to Anchorage Seating in Service DC Ratio, DC = | B25: =Calculation!W337 -> 0.90409256
A27: =Calculation!V339 -> Eff. Post-Tensioning Stress at Start of Span in Service, fpe.service.L2 = | B27: =Calculation!W339 -> 1206.947
A28: =Calculation!V340 -> Stress Limit Prior to Anchorage Seating in Service, fpu.service.lim = | B28: =Calculation!W340 -> 1340.3408
A29: =Calculation!V341 -> Stress Limit Prior to Anchorage Seating in Service DC Ratio, DC = | B29: =Calculation!W341 -> 0.90047767
A31: =Calculation!V343 -> Eff. Post-Tensioning Stress at Midspan in Service, fpe.service.L3= | B31: =Calculation!W343 -> 1295.9953
A32: =Calculation!V344 -> Stress Limit Prior to Anchorage Seating in Service, fpu.service.lim = | B32: =Calculation!W344 -> 1340.3408
A33: =Calculation!V345 -> Stress Limit Prior to Anchorage Seating in Service DC Ratio, DC = | B33: =Calculation!W345 -> 0.96691474

Sheet Template Notes
A1: Template Formatting Notes
A2: 1 | B2: Rows and Columns always 20 pixels
A3: 2 | B3: Use font 9 and type 'Jacobs Chronos' for calcs
A4: 3 | B4: Keep Scale always set to 100% (Page Layout Tab > Scale to Fit > Scale:)
A5: 4 | B5: Top and Bottom Margins set to 0.30"; left and right margins set to 0.25"; Header set to 0.30"; Footer set to 0.00" (Page Layout Tab > Page Setup > Margins Tab)
A6: 5 | B6: Select 'Horiontally' under 'Center on Page' section (Page Layout Tab > Page Setup > Margins Tab)
A7: 6 | B7: Set "$1:$7" in 'Rows to Repeat' (Page Layout > Page Setup > Sheet Tab)
A8: 7 | B8: Excel sets column and row size based on screen pixels. Windows has a setting to scale screen pixels (Display Settings > Scale & Layout > Scale). The amount of space a column or row takes up on the page is directly affected by the windows scale for screen pixels; thus a spreadsheet will print differently if users have different windows pixel scales. Tools have been develped to print with a windows pixel scale of 100%, and the windows pixel scale should be set to this before printing to achieve proper formating.
