Workbook
Name Demand_M.u.Negative: Calculation!$W$319
Name Demand_M.u.Positive: Calculation!$W$237
Name Geometry_a.Negative: Calculation!$AN$350
Name Geometry_a.Positive: Calculation!#REF!
Name Geometry_b.Negative: Calculation!$W$336
Name Geometry_b.Positive: Calculation!$W$253
Name Geometry_b.w: Calculation!$W$248
Name Geometry_c.Negative: Calculation!$AN$347
Name Geometry_c.Positive: Calculation!#REF!
Name Geometry_d.p.Negative: Calculation!$W$329
Name Geometry_d.p.Positive: Calculation!$W$246
Name Geometry_d.s.Negative: Calculation!$W$330
Name Geometry_d.s.Positive: Calculation!$W$247
Name Geometry_GirderLocation: Calculation!#REF!
Name Geometry_h.f.Negative: Calculation!$W$332
Name Geometry_h.f.Positive: Calculation!$W$249
Name Geometry_S: Calculation!$W$251
Name Geometry_S.OH: Calculation!$W$252
Name Geometry_SectionType.Positive: Calculation!#REF!
Name Geometry_x.u.Positive: Calculation!$W$236
Name Mat.Conc_Alpha.1: Calculation!$W$257
Name Mat.Conc_Beta.1: Calculation!$W$256
Name Mat.Conc_f.c: Calculation!$W$245
Name Mat.PT_A.ps: Calculation!$W$240
Name Mat.PT_E.ps: Calculation!$W$239
Name Mat.PT_E.s: Calculation!$W$238
Name Mat.PT_epsilon.t2: Calculation!#REF!
Name Mat.PT_f.pe: Calculation!$W$243
Name Mat.PT_f.ps: Calculation!#REF!
Name Mat.PT_f.pu: Calculation!$W$242
Name Mat.PT_f.py: Calculation!$W$244
Name Mat.PT_k: Calculation!$W$255
Name Mat.PT_phi: Calculation!#REF!
Name Mat.Rebar_A.s.Positive: Calculation!$W$241
Name Mat.Rebar_epsilon.cl: Calculation!$W$254
Name Mat.Rebar_epsilon.tl: Calculation!$W$300
Name Mat.Rebar_f.y: Calculation!$W$250
Name Resistance_M.n.Negative: Calculation!$AN$351
Name RF_phi: Calculation!$AN$352
Name Table_DC: Calculation!$BO$674:INDEX(Calculation!$BO$674:$BO$774, MATCH(TRUE, Calculation!$BO$674:$BO$774="", 0) - 1)
Name Table_Location: Calculation!$H$674:INDEX(Calculation!$H$674:$H$774, MATCH(TRUE, Calculation!$H$674:$H$774="", 0) - 1)
Name Table_Mr_neg: Calculation!$BI$674:INDEX(Calculation!$BI$674:$BI$774, MATCH(TRUE, Calculation!$BI$674:$BI$774="", 0) - 1)
Name Table_Mr_pos: Calculation!$AH$674:INDEX(Calculation!$AH$674:$AH$774, MATCH(TRUE, Calculation!$AH$674:$AH$774="", 0) - 1)
Name Table_Mu: Calculation!$BL$674:INDEX(Calculation!$BL$674:$BL$774, MATCH(TRUE, Calculation!$BL$674:$BL$774="", 0) - 1)
Name TEMPLATE_VERSION: Inputs!$I$1

Sheet Guidance and Scope
A1: Scope
A2: 1 | B2: Maximum nodes is 100
A3: 2 | B3: Maximum skew angle of 75°, where skew angle is the angle between the bearing line and a line normal to the centerline girder. For skew angles larger than this, a refined analysis is required to determine the effective flange width; see AASHTO 4.6.2.6 for more details.
A4: 3 | B4: Maximum L/S of 2.0, where L is the span length and S is the girder spacing. For L/S greater than this, a refined analysis is required to determine the effective flange width; see AASHTO 4.6.2.6 for more details.
A5: 4 | B5: Maximum overhang widths of 0.5S, where S is the girder spacing. For overhang widths greater than this, a refined analysis is required to determine the effective flange width; see AASHTO 4.6.2.6 for more details.

Sheet Inputs
A1: Specified Tensile Strength of Prestressing Steel, fpu = | B1: 270 | C1: ksi | F1: TEMPLATE_VERSION | I1: 1.0.0
A2: Effective stress in Prestressing Steel, fpe = | B2: 233 | C2: ksi
A3: Post-Tensioning Yield Strength, fpy = | B3: 243 | C3: ksi
A4: Concrete Compressive Strength, f'c = | B4: 5 | C4: ksi
A5: Reinforcing Yield Strength, fy = | B5: 60 | C5: ksi
A6: Reinforcing Steel Modulus of Elasticity, Es = | B6: 29000 | C6: ksi
A7: Post-Tensioning Steel Modulus of Elasticity, Ep = | B7: 28500 | C7: ksi
A8: Girder Spacing, S = | B8: 8 | C8: ft
A9: Overhang Width, SOH = | B9: 3.5 | C9: ft
A10: Overall Depth of Beam, h = | B10: 100 | C10: in
A11: Girder Location = | B11: Interior
A12: Project Name | B12: North Connector Bridge
A13: Jacobs Project Number | B13: 405845
A14: Section Letter | B14: C.1
A15: Originator Initials | B15: NCB
A16: Origination Date | B16: 46006
A17: Checker Initials | B17: DA
A18: Checked Date | B18: 46009
A19: Revision Number | B19: 1
A22: NODE | B22: DISTANCE ALONG SPAN, Li | C22: FACTORED STRENGTH 1 FLEXURE, Mu | D22: Aps | E22: bw | F22: dp | G22: Bottom Flange | K22: Top Flange
G23: As | H23: ds | I23: hf | J23: b | K23: As | L23: ds | M23: hf | N23: b
A24: - | B24: ft | C24: kips ft | D24: in2 | E24: in | F24: in | G24: in2 | H24: in | I24: in | J24: in | K24: in2 | L24: in | M24: in | N24: in
J25: =IF($B$11="Exterior",0.5*$B$8+$B$9,$B$8)*12 -> 96
J26: =IF($B$11="Exterior",0.5*$B$8+$B$9,$B$8)*12 -> 96
J27: =IF($B$11="Exterior",0.5*$B$8+$B$9,$B$8)*12 -> 96
J28: =IF($B$11="Exterior",0.5*$B$8+$B$9,$B$8)*12 -> 96
J29: =IF($B$11="Exterior",0.5*$B$8+$B$9,$B$8)*12 -> 96
J30: =IF($B$11="Exterior",0.5*$B$8+$B$9,$B$8)*12 -> 96
J31: =IF($B$11="Exterior",0.5*$B$8+$B$9,$B$8)*12 -> 96
J32: =IF($B$11="Exterior",0.5*$B$8+$B$9,$B$8)*12 -> 96
J33: =IF($B$11="Exterior",0.5*$B$8+$B$9,$B$8)*12 -> 96
J34: =IF($B$11="Exterior",0.5*$B$8+$B$9,$B$8)*12 -> 96
J35: =IF($B$11="Exterior",0.5*$B$8+$B$9,$B$8)*12 -> 96
J36: =IF($B$11="Exterior",0.5*$B$8+$B$9,$B$8)*12 -> 96
... J124: =IF($B$11="Exterior",0.5*$B$8+$B$9,$B$8)*12 -> 96

Sheet Calculation
BF1: COMPUTATION SHEET | BR1: Page:
BR2: Originator: | BV2: =Inputs!B15 -> NCB
BR3: Date: | BV3: =Inputs!B16 -> 46006
A4: Project Name: | E4: =Inputs!B12 -> North Connector Bridge | BR4: Checker: | BV4: =Inputs!B17 -> DA
A5: Project No.: | E5: =Inputs!B13 -> 405845 | BR5: Date: | BV5: =Inputs!B18 -> 46009
A6: Section: | E6: =Inputs!B14&" Strength 1 Flexure Check" -> C.1 Strength 1 Flexure Check | BR6: Revision No.: | BV6: =Inputs!B19 -> 1
A8: =Inputs!B14&" Factored Flexural Resistance of Post-Tensioned Multicell Box Girder " -> C.1 Factored Flexural Resistance of Post-Tensioned Multicell Box Girder
BS9: Equation or Reference
C10: 1 | E10: Introduction
E12: This calculation determines the factored flexural resistance of a post‑tensioned concrete beam in accordance with AASHTO LRFD Bridge Design Specifications, Article 5.6.3.2. The intent of this calculation is to establish a clear, transparent, and consistent evaluation of the nominal and factored flexural resistance based primarily on the contribution of the post‑tensioning steel, mild (non-prestressed) reinforcing tensile steel, and concrete compression block. For the purposes of this calculation, the contribution from mild (non‑prestressed) reinforcing compression steel is intentionally neglected in both positive and negative flexure., since compression reinforcing typically offers minimal increase to the resistance of the member. This simplification is made for consistency, clarity, and to avoid unnecessary analytical complexity.
C18: 1.1. | G18: Treatment of Mild Reinforcing Steel
G20: Including mild reinforcing steel in flexural resistance calculations introduces additional complexity because the stress in the reinforcing steel is not known beforehand. Unlike prestressing steel, which is typically assumed to reach a known effective stress at ultimate, mild reinforcing steel may or may not yield at the nominal strength condition. AASHTO LRFD recognizes this explicitly by using the reinforcing steel stress, fs, instead of the reinforcing yield strength, fy, in its flexural resistance equation (AASHTO 5.6.3.2.2-1). Determining fs​ requires:
G25: 1 | I25: An initial assumption (commonly fs = fy),
G26: 2 | I26: Calculation of the steel strain, εt, based on strain compatibility,
G27: 3 | I27: Verification of yielding by comparing εt to the limiting steel tensile strain, εtl (typically 0.005 for mild reinforcing with a yield strength of 60 ksi), and
G28: 4 | I28: Recalculation of steel stress and moment capacity if the reinforcing has not yielded.
G30: ="If the reinforcing strain is less than the yield strain, the steel stress must be computed from the strain, and the flexural resistance must be recalculated. This process is best handeled through an iterative approach. Table "&Inputs!B14&"-1 and "&Inputs!B14&"-2 step through this iterative approach in detail for the locations in the beam with maximum and minimum flexural demand; Tables "&Inputs!B14&"-3 and "&Inputs!B14&"-4 provide information on the strain compatibility iteration for each location along the beam." -> If the reinforcing strain is less than the yield strain, the steel stress must be computed from the strain, and the flexural resistance must be recalculated. This process is best handeled through an iterative approach. Table C.1-1 and C.1-2 step through this iterative approach in detail for the locations in the beam with maximum and minimum flexural demand; Tables C.1-3 and C.1-4 provide information on the strain compatibility iteration for each location along the beam.
C33: 1.2. | G33: Interpretation of Tensile Strain Limits for Prestressed Concrete Members
G35: The resistance factor for post-tensioned members is calculated using AASHTO Equation 5.5.4.2-1, with the net tensile strain (total strain from post-tensioning and applied external loads), εt, determined as the net tensile strain in the post-tensioned reinforcing at nominal flexural resistance. The tensile strain limits referenced in AASHTO Equation 5.5.4.2-1 are determined from AASHTO Table C5.6.2.1-1 for reinforcing with a specified minimum yield strength of 60-ksi (e.g., 0.0020 for compression‑controlled behavior and 0.0050 for tension‑controlled behavior) ; the tensile strain limits are used to classify sectional ductility and to determine the appropriate flexural resistance factor, φ. However, it is important to recognize that these limits do not correspond to yielding behavior of prestressing steel and should not be interpreted as material strain limits. The strain thresholds commonly cited in AASHTO were originally developed for Grade 60 mild reinforcing steel. Grade 60 reinforcing steel exhibits a well‑defined yield point, with a yield strain on the order of 0.002, followed by a relatively flat yield plateau that allows for significant inelastic deformation prior to fracture. For reinforced concrete members, these strain limits therefore have a direct physical meaning, as they indicate whether reinforcing steel has yielded and whether the member can undergo large rotations in a ductile manner. Post-tensioning steel behaves fundamentally differently. Seven‑wire prestressing strand (ASTM A416) does not exhibit a distinct yield point or yield plateau. Instead, its stress–strain relationship is:
H42: • | I42: Essentially linear at low strains,
H43: • | I43: Gradually nonlinear at higher stresses, and
H44: • | I44: Characterized by a smooth transition toward ultimate strength, followed by rupture.
G46: Because of this behavior, post-tensioning steel does not have a unique yield strain analogous to mild reinforcing steel. Consequently, strain limits such as εt = 0.005 should not be interpreted as indicating yielding of post-tensioned steel. In addition, post-tensioning steel possesses a significant initial tensile strain due to effective prestress prior to application of external loads. The net tensile strain used in calculating the AASHTO resistance‑factor for post-tensioning includes both the initial prestress strain, εt1 (calculated as the effective post-tensioning stress divided by the modulus of elasticity of the post-tensioning material), and additional strain induced by flexural curvature under factored loads, εt2. As a result, post-tensioning steel often exceeds the numerical tensile strain limits used in Article 5.5.4.2 even when the section behavior remains relatively brittle compared to reinforced concrete members with yielding reinforcing steel. For post-tensioned concrete members, the tensile strain limits in Article 5.5.4.2 should therefore be understood as ductility classification thresholds, not material yield limits. Their purpose is to:
H52: • | I52: Reflect the relative rotation capacity of the section,
H53: • | I53: Penalize sections with limited warning prior to failure (e.g., concrete crushing or strand rupture), and
H54: • | I54: Provide a calibrated reduction in resistance factor consistent with observed structural performance.
G56: Accordingly, when applying Equation 5.5.4.2‑2 to post-tensioned concrete beams, the calculated resistance factor reflects member‑level ductility, not yielding of post-tensioned steel. Care should be taken to avoid equating numerical strain thresholds with physical yielding behavior when interpreting results for post-tensioned members.
C59: 1.3. | G59: Effective Flange Width
G61: Per AASHTO 4.6.2.6.1, the effective flange width may be taken as the tributary width perpendicular to the axis of the member for determining flexural resistance. In these calculations the effective flange width is taken as one-half the distance to the adjacent girder on each side of the component, or one-half the distance to the adjacent girder plus the full overhang width. The commentary of AASHTO 4.6.2.6.1 notes that these provisions are considered applicable for skew angles less than or equal to 75° (where skew angle is the angle between the bearing line and a line normal to the centerline girder), L/S greater than or equal to 2.0 (where L is the span length and S is the center to center spacing of girders, and overhang widths less than or equal to 0.5S. The provisions are considered applicable for slab-beam bridges with unequal skew angles of the bearing lines, splayed girders, horizontally curved girders, cantilever spans, and various unequal span lengths of continuous spans. The use of one-half the distance to the adjacent girder in calculating the effective width of the main girders in composite girder systems is a conservative assumption for the main structural components, since typically a larger width of the slab can be expected to participate with the main girders. To utilize a larger effective slab width for the main girders, a more refined analysis is needed and falls outside the scope of this calculation tool.
C68: 1.4. | G68: Bonded and Unbonded Tendons
G70: This calculation tool does not consider the effects of unbonded tendons; all post-tensioning is assumed to be bonded.
C72: 1.5. | G72: Limitations and Future Enhancements
G74: The current version of this spreadsheet is intended to provide a rational strain-compatibility–based estimate of the flexural resistance of a multicell post-tensioned concrete box girder. While suitable for many practical applications, several simplifying assumptions have been made. The following limitations have been identified, along with planned enhancements for future versions:
H77: • | I77: Steel Development Assumptions - All mild reinforcing steel and prestressing steel are assumed to be fully developed at each section considered. Effects associated with insufficient development length, debonding, or incomplete anchorage are not currently considered. Future enhancements will incorporate checks for developed length and apply appropriate reductions to section capacity where reinforcement or prestressing steel is not fully developed.
H79: • | I79: Graphical Representation of Section Properties - At present, the spreadsheet does not include a graphical depiction of the girder cross section or reinforcement layout. A future version may add plots of the girder section at the end region and at midspan as well as an elevation view of the girder to illustrate the geometry, prestressing centroid, and mild reinforcement centroid variations along the girder length.
H81: • | I81: Steel Rupture Limits - The spreadsheet assumes that neither prestressing steel nor mild reinforcing steel ruptures prior to reaching the calculated flexural resistance. While it is uncommon for steel rupture to govern the flexural capacity of post-tensioned box girders, ASTM specifications define ultimate strain limits for both mild steel reinforcing and prestressing steel. Future versions should incorporate rupture strain limits to prevent unconservative predictions in cases where steel fracture may control.
H84: • | I84: Material Stress–Strain Models - Concrete and prestressing steel behavior are currently represented using stress–strain relationships consistent with AASHTO provisions. While appropriate for most design applications, these models are idealized. Future enhancements could include user selectable alternative material models—such as refined nonlinear models for unconfined concrete and prestressing steel —to improve accuracy for advanced analyses.
H87: • | I87: Compression Reinforcement Contribution - The contribution of compression reinforcement to flexural resistance is currently neglected. Although often small for typical box girder sections, inclusion of compression steel would improve completeness and accuracy in sections where meaningful compression reinforcement is present. This capability may be added in future versions of the spreadsheet.
C95: 2 | E95: Design Equations and Nomenclature
E97: The nomenclature and equations used throughout this calculation tool is described in this section.
...

Sheet Outputs
A1: Positive Flexural Resistance
A2: Prestressing Stress Limit Coefficient, k = | B2: =Mat.PT_k -> 0.28 | I2: Abbreviations
A3: Stress Block Factor, ϐ1 = | B3: =Mat.Conc_Beta.1 -> 0.8 | E3: References | G3: Design Assumptions | I3: Abbreviation | J3: Definition
A4: Stress Block Factor, α1 = | B4: =Mat.Conc_Alpha.1 -> 0.85 | E4: AASHTO, 10th | G4: Flexural Analysis Methodology - The flexural behavior of post-tensioned concrete box girders is evaluated using classical flexural theory, assuming that plane sections remain plane after bending. | I4: Dist. | J4: Distance
A5: Neutral Axis of section, c = | B5: =Calculation!W290 -> #VALUE! | G5: Strain Distribution - A linear strain distribution is assumed across the depth of the post-tensioned box section for the calculation of flexural resistance. | I5: Ext. | J5: Extreme
A6: Compression Depth, a = | B6: =Calculation!W291 -> #VALUE! | G6: Torsional Effects - Torsional effects are considered negligible and are therefore excluded from both flexural resistance and demand calculations. | I6: PT | J6: Post-Tensioning
I7: N.A. | J7: Neutral Axis
I8: Equiv. | J8: Equivalent
A9: Resistance Reduction Factor, ϕ = | B9: =Calculation!W302 -> #VALUE! | I9: Btw | J9: Between
A10: Factored Strength 1 Flexural Resistance, ϕMn = | B10: =Calculation!W312 -> #VALUE! | I10: NPT | J10: Non-Post-Tensioned
A11: Factored Strength 1 Demand to Capacity Ratio, D/C = | B11: =Calculation!W313 -> #VALUE! | I11: Reinf. | J11: Reinforcing
A12: Negative Flexural Resistance
A13: Neutral Axis of section, c = | B13: =Calculation!W378 -> #VALUE!
A14: Compression Depth, a = | B14: =Calculation!W379 -> #VALUE!
A15: Resistance Reduction Factor, ϕ = | B15: =Calculation!W390 -> #VALUE!
A16: Factored Strength 1 Flexural Resistance, ϕMn (-) = | B16: =Calculation!W400 -> #VALUE!
A17: Factored Strength 1 Demand to Capacity Ratio, D/C = | B17: =Calculation!W401 -> #VALUE!

Sheet Template Notes
A1: Template Formatting Notes
A2: 1 | B2: Rows and Columns always 20 pixels
A3: 2 | B3: Use font 9 and type 'Jacobs Chronos' for calcs
A4: 3 | B4: Keep Scale always set to 100% (Page Layout Tab > Scale to Fit > Scale:)
A5: 4 | B5: Top and Bottom Margins set to 0.30"; left and right margins set to 0.25"; Header set to 0.30"; Footer set to 0.00" (Page Layout Tab > Page Setup > Margins Tab)
A6: 5 | B6: Select 'Horiontally' under 'Center on Page' section (Page Layout Tab > Page Setup > Margins Tab)
A7: 6 | B7: Set "$1:$7" in 'Rows to Repeat' (Page Layout > Page Setup > Sheet Tab)
A8: 7 | B8: Excel sets column and row size based on screen pixels. Windows has a setting to scale screen pixels (Display Settings > Scale & Layout > Scale). The amount of space a column or row takes up on the page is directly affected by the windows scale for screen pixels; thus a spreadsheet will print differently if users have different windows pixel scales. Tools have been develped to print with a windows pixel scale of 100%, and the windows pixel scale should be set to this before printing to achieve proper formating.
