Workbook
Name A.ps: Calculation!$X$245
Name b.s: Calculation!$X$270
Name b.w1: Calculation!$X$147
Name b.w2: Calculation!$X$148
Name BS.F11: Calculation!$X$310
Name BS.F12: Calculation!$X$311
Name BS.F13: Calculation!$X$312
Name BS.F14: Calculation!$X$313
Name c.g._bot: Calculation!$X$327
Name c.g._spc_tendons: Calculation!$X$326
Name c.g._top: Calculation!$X$328
Name c.g.comb.: Calculation!$X$306
Name c.g.ext.f: Calculation!$X$292
Name c.g.int.f: Calculation!$X$297
Name c.g.overhang: Calculation!$X$287
Name c.g.web: Calculation!$X$302
Name CG.BS: Calculation!$X$314
Name CG.OFW: Calculation!$X$307
Name CG.TS: Calculation!$X$282
Name Comb.F: Calculation!$X$305
Name D.bs: Calculation!$X$152
Name e.genzone: Calculation!$X$261
Name EF.F5: Calculation!$X$290
Name EF.F6: Calculation!$X$291
Name f.s: Calculation!$X$268
Name fci: Calculation!$X$456
Name fpu: Calculation!$X$246
Name fy: Calculation!$X$428
Name H.bs: Calculation!$X$158
Name H.o: Calculation!$X$159
Name H.ts: Calculation!$X$156
Name Hf.ext: Calculation!$X$277
Name Hf.int: Calculation!$X$275
Name Hw.ext: Calculation!$X$674
Name IF.F7: Calculation!$X$295
Name IF.F8: Calculation!$X$296
Name J.5_y_Coord: Calculation!$X$322
Name J.7_x_Coord: Calculation!$X$332
Name J.7_y_Coord: Calculation!$X$331
Name J.8_x_Coord: Calculation!$X$336
Name J.8_y_Coord: Calculation!$X$335
Name L.A: Calculation!$X$149
Name L.anchorage: Calculation!$X$206
Name L.b: Calculation!$X$151
Name L.bf: Calculation!$X$157
Name L.bs: Calculation!$X$153
Name L.CL1: Calculation!$X$144
Name L.CL2: Calculation!$X$145
Name L.ds: Calculation!$X$155
Name L.F: Calculation!$X$146
Name L.Gz: Calculation!$X$214
Name L.Lz: Calculation!$X$207
Name L.oh: Calculation!$X$160
Name L.s: Calculation!$X$154
Name m.I: Calculation!$X$222
Name N.B: Calculation!$X$432
Name N.B1: Calculation!$X$762
Name N.BT: Calculation!$X$251
Name N.S: Calculation!$X$442
Name N.T1: Calculation!$X$586

Sheet Guidance and Scope
A1: 1. Guidance
A3: This spreadsheet provides guidance for the design and verification of the end block (anchorage zone) of a post‑tensioned multicell concrete box girder bridge. The calculation methodology is based on the provisions of AASHTO LRFD Bridge Design Specifications, 10th Edition, and reflects commonly accepted bridge engineering practice for post‑tensioned anchorage zones. The anchorage zone is treated as a disturbed region (D‑region) where the classical assumption that plane sections remain plane is not valid due to the highly concentrated prestressing forces. Accordingly, the strut‑and‑tie method is employed to model the force flow and to determine reinforcement demands and concrete stresses. Simplified equilibrium‑based approaches are used where appropriate to maintain transparency, traceability, and computational efficiency. This spreadsheet guides the user through:
A10: • | C10: definition of anchorage geometry and section properties, including the effects of flared webs,
A11: • | C11: determination of local and general anchorage zones,
A12: • | C12: resolution of factored prestressing forces into horizontal and vertical components,
A13: • | C13: evaluation of stresses and resultant forces at the end of the anchorage zone,
A14: • | C14: development and solution of strut‑and‑tie models for the anchorage zone, top slab, and bottom slab,
A15: • | C15: design of bursting and spalling reinforcement,
A16: • | C16: verification of concrete compressive stresses beyond the local zone.
A17: The spreadsheet is intended to be used by experienced structural or bridge engineers familiar with post‑tensioned concrete design and AASHTO LRFD requirements. Engineering judgment is required when interpreting results and applying them to project‑specific conditions.
A20: 2. Scope
A22: The scope of this spreadsheet is limited to the design and verification of the end block (anchorage zone) for a post‑tensioned multicell concrete box girder with internal and exterior webs. Specifically, the spreadsheet covers the following:
A25: • | C25: End block and anchorage zone geometry definition, including web flaring and diaphragm location.
A26: • | C26: Determination of local zone and general zone lengths in accordance with AASHTO LRFD.
A27: • | C27: Calculation of section properties at the end of the anchorage zone.
A28: • | C28: Determination of anchorage zone stresses and resultant forces based on factored prestressing forces.
C29: Strut‑and‑tie modeling of:
A30: • | D30: the anchorage zone,
A31: • | D31: the top slab anchorage region,
A32: • | D32: the bottom slab anchorage region.
C33: Design of:
A34: • | D34: web bursting reinforcement,
A35: • | D35: spalling reinforcement near anchorage faces,
A36: • | D36: transverse reinforcement in the top slab,
A37: • | D37: transverse reinforcement in the bottom slab.
C38: Verification of concrete compressive stresses at:
A39: • | D39: the local zone / general zone interface,
A40: • | D40: the end of the diaphragm.
A41: The following items are outside the scope of this spreadsheet:
A43: • | C43: detailed design of anchorage hardware and proprietary post‑tensioning components,
A44: • | C44: detailed concrete stress checks within the immediate anchorage head local zone,
A45: • | C45: time‑dependent effects such as creep, shrinkage, relaxation, and long‑term prestress losses,
A46: • | C46: global girder analysis or service‑level stress checks outside the anchorage region,
A47: • | C47: applicability to external post‑tensioning systems or non‑standard anchorage layouts without modification.
A48: The spreadsheet is formulated for routine bridge design applications. Use for geometries, loading conditions, or structural systems significantly different from those assumed herein may require modification of the methodology and independent verification.

Sheet Inputs
A1: Project Name | B1: North Connector Bridge | M1: TEMPLATE_VERSION | P1: 1.0.0
A2: Jacobs Project Number | B2: 408545
A3: Section | B3: C.1
A4: Originator | B4: TG
A5: Date | B5: 46305
A6: Checker | B6: SB
A7: Date | B7: 46091
A8: Revision No. | B8: 1
I9: Note: Max number of spacing is 21
A10: Number of internal webs, Nweb = | B10: 4 | E10: No. | I10: Spacing btw webs for Top Slab (m) | O10: Spacing btw webs for Bot Slab (m)
A11: Front of Diaphragm to CL of Bridge Abut, LCL1 = | B11: =1.5*12*0.0254 -> 0.4572 | E11: m
A12: Back of Diaphragm to CL of Bridge Abut, LCL2 = | B12: =2*12*0.0254 -> 0.6096 | E12: m | I12: =38*0.0254 -> 0.9652 | O12: =71.04*0.0254 -> 1.804416
A13: Web Flare Length, LF = | B13: =16*12*0.0254 -> 4.8768 | E13: m | I13: =93.5*0.0254 -> 2.3749 | O13: =93*0.0254 -> 2.3622
A14: Beginning Web Flare Width, bw1 = | B14: =18*0.0254 -> 0.4572 | E14: m | I14: =93*0.0254 -> 2.3622 | O14: =93*0.0254 -> 2.3622
A15: Ending Web Flare Width, bw2 = | B15: =12*0.0254 -> 0.3048 | E15: m | I15: =93*0.0254 -> 2.3622 | O15: =93*0.0254 -> 2.3622
A16: Bottom Length of Anchore Blockout, LA = | B16: =9*0.0254 -> 0.2286 | E16: m | I16: =93*0.0254 -> 2.3622 | O16: =71.04*0.0254 -> 1.804416
A17: Angle at which exterior web is placed β = | B17: 21.8 | E17: deg | I17: =93.5*0.0254 -> 2.3749
A18: Min Distance from Bottom Slab to CL of Strands at Midspan, Dbs = | B18: =12*0.0254 -> 0.3048 | E18: m | I18: =38*0.0254 -> 0.9652
A19: Beggining of Strands Bending counting from Bearing CL, Lbs = | B19: =52*12*0.0254 -> 15.8496 | E19: m
A20: Span Length, Ls = | B20: =130*12*0.0254 -> 39.624 | E20: m
A21: Top Slab Width, Lds = | B21: =542*0.0254 -> 13.7668 | E21: m
A22: Top Slab Thickness, Hts = | B22: =8*0.0254 -> 0.2032 | E22: m
A23: Bottom Slab Width, Lbf = | B23: =436*0.0254 -> 11.0744 | E23: m
A24: Bottom Slab Thickness, Hbs = | B24: =6*0.0254 -> 0.1524 | E24: m
A25: Overhang Thickness, Ho = | B25: =9*0.0254 -> 0.2286 | E25: m
A26: Overhang Width, Loh = | B26: =(63/2)*0.0254 -> 0.8001 | E26: m
A27: Maximum Width of Local Zone, Wlz = | B27: =16.4*0.0254 -> 0.41656 | E27: m
A28: Length of Anchorage Device Confining Reinforcement, Lanchorage = | B28: =15*0.0254 -> 0.381 | E28: m
A29: Section Height, Sh = | B29: =5.5*12*0.0254 -> 1.6764 | E29: m
A30: Section Width, Sw = | B30: =93*0.0254 -> 2.3622 | E30: m
A31: Area of section, Sa = | B31: =12349*0.00064516 -> 7.9670808 | E31: m2
A32: Moment of Interia mI = | B32: =7160048*0.000000416231426 -> 2.980237 | E32: m4
A33: Distance to Bottom Fiber, ybf = | B33: =36.831*0.0254 -> 0.9355074 | E33: m
A34: Distance to Top Fiber, ytf = | B34: =29.169*0.0254 -> 0.7408926 | E34: m | G34: 0
A35: Number of Strands, No.str = | B35: 200 | E35: No.
A36: Aera of Strand, Aps = | B36: =0.217*6.4516 -> 1.3999972 | E36: cm2
A37: Tensile Strength, fpu = | B37: =270*6.8947572932 -> 1861.5845 | E37: Mpa
A38: Number of Strands in Top Tendon, NTT = | B38: =17*6 -> 102 | E38: No.
A39: Number of Strands in Bottom Tendon, NBT = | B39: =16*4+17*2 -> 98 | E39: No.
A40: Interior Fillet Height, Hf_int = | B40: =4*0.0254 -> 0.1016 | E40: m
...

Sheet Calculation
BG1: COMPUTATION SHEET | BS1: Page:
BS2: Origmator: | BW2: =Inputs!B4 -> TG
BS3: Date: | BW3: =Inputs!B5 -> 46305
A4: Project Name: | E4: =Inputs!B1 -> North Connector Bridge | BS4: Checker: | BW4: =Inputs!B6 -> SB
A5: Project No.: | E5: =Inputs!B2 -> 408545 | BS5: Date: | BW5: =Inputs!B7 -> 46091
A6: Section: | E6: =Inputs!B3 &" Design of Anchor Zone" -> C.1 Design of Anchor Zone | BS6: Revision No.: | BW6: =Inputs!B8 -> 1
A8: =Inputs!B3&" End Block Design" -> C.1 End Block Design
BT9: Equation or Reference
C10: 1 | E10: Introduction
E12: This calculation presents the design of the end block (anchorage zone) for a post‑tensioned multicell concrete box girder bridge, in accordance with the AASHTO LRFD Bridge Design Specifications, 10th Edition. The end block is required to safely transfer the highly concentrated post‑tensioning anchorage forces into the bridge superstructure while maintaining acceptable concrete stresses and providing adequate reinforcement to resist tensile splitting and bursting forces. Within the anchorage zone, the standard assumption that plane sections remain plane is not valid due to the nonlinear stress flow caused by the concentrated prestressing forces. Accordingly, this calculation evaluates the anchorage zone using the strut‑and‑tie modeling approach, which is explicitly permitted by AASHTO LRFD for disturbed regions (D‑regions) and is well suited for complex stress distributions occurring near prestressing anchorages. The analysis includes:
F19: • | G19: Geometric definition of the local zone, general zone, and overall anchorage zone,
F20: • | G20: Determination of section properties at the end of the anchorage zone accounting for web flaring,
F21: • | G21: Resolution of post‑tensioning forces into horizontal and vertical components,
F22: • | G22: Evaluation of stress distributions and corresponding forces in the top slab, webs, fillets, and bottom slab,
F23: • | G23: Construction and solution of strut‑and‑tie models for the anchorage zone, top slab, and bottom slab,
F24: • | G24: Design checks for bursting reinforcement, spalling reinforcement, and concrete compressive stresses.
E26: This calculation is implemented in a spreadsheet format intended to provide a transparent, traceable, and repeatable design procedure consistent with established AASHTO LRFD examples and commonly accepted bridge engineering practice.
C29: 1.1. | G29: Design Limitations
G31: The design methodology and spreadsheet are subject to the following limitations:
G33: 1 | I33: Assumed Tendon Geometry Near Anchorage
I34: Tendons are assumed to be straight near the anchorage device, consistent with post‑tensioning hardware and trumpet geometry. Parabolic or deviated tendon behavior beyond the anchorage zone is not considered in this portion of the analysis.
G36: 2 | I36: Local Zone Concrete Capacity
I37: Concrete stresses within the local zone immediately ahead of the anchorage device are not checked in detail. It is assumed that anchorage hardware, confining reinforcement, and testing provided by the post‑tensioning system supplier satisfy AASHTO requirements. Concrete stress checks are performed only at the local zone / general zone interface and at critical geometric discontinuities.
G39: 3 | I39: Simplified Slab Distribution Assumptions
I40: For the top and bottom slabs, simplified load distribution assumptions are used to generate the strut‑and‑tie models. Full elasticity‑based slab behavior is not evaluated. The bottom slab model specifically assumes non‑uniform distribution due to the sloped exterior web and absence of a bottom cantilever.
G42: 4 | I42: Material Behavior
I43: Reinforcing steel is assumed to behave elastically up to yield with yielding permitted in tension ties. Concrete is assumed to remain uncracked in compression struts. Long‑term effects such as creep, shrinkage, relaxation, and time‑dependent redistribution of stresses are not directly evaluated.
G45: 5 | I45: Bridge Configuration
I46: The spreadsheet is formulated for multicell box girders with flared webs and discrete anchorage groupings. Application to significantly different geometries, atypical anchorage layouts, or external post‑tensioning systems may require modification of the model.
C52: 1.2. | G52: Selection of Strut‑and‑Tie Method
G54: The strut‑and‑tie method was selected over refined elastic stress analysis and approximate methods because it more accurately represents the force flow in the anchorage region of box girders. Approximate methods may not adequately capture the I‑shaped behavior of the cross section, while refined elastic analyses can become unnecessarily complex for routine bridge design. For slab strut‑and‑tie models, a complete nodal equilibrium solution is not performed. Instead, free‑body diagrams and moment equilibrium are used to determine critical tension tie forces. This approach is consistent with the referenced LRFD example and provides sufficient accuracy for reinforcement design while maintaining calculation efficiency.
C59: 1.3. | G59: Definition of Local / General Zones and Concrete Stress Checks
G61: Local zone dimensions are based on anchorage hardware and confining reinforcement requirements, while the general zone is governed by the maximum depth or width of the section. The chosen lengths are consistent with AASHTO LRFD limits. Several simplifications—such as assuming uniform distribution at the end of the general zone and using widened web dimensions—introduce conservatism into the design. Concrete stress limits are evaluated using factored prestressing forces and resistance factors appropriate for anchorage zones. The stress‑spreading assumption of a 1:3 slope is used to assess stresses at the local/general zone interface and at the diaphragm discontinuity, providing a conservative but practical approach.
C96: 2 | E96: Notation
E98: The nomenclature used throughout this calculation tool is described in this section.
C101: 2.1. | G101: Description of Variables
F104: Aps = | G104: aera of strand (cm2) | AB104: Lbs = | AC104: beginning of strands bending counting from bearing CL (m) | AX104: Sw = | AY104: section width (m)
F105: As.prov = | G105: provided aera of reinforcement (m2) | AB105: LCL_e = | AC105: distance from CL of edge of bottom slab to end of slab (m) | AX105: ts = | AY105: general zone stress distribution at upper edge on top flange (MPa)
F106: As.req = | G106: required aera of reinforcement (m2) | AB106: LCL1 = | AC106: front of diaphragm to CL of bridge abutment (m) | AX106: tbs = | AY106: general zone stress distribution at bottom edge on top flange (MPa)
F107: bs = | G107: general zone stress distribution at bttom edge on bottom flange (MPa) | AB107: LCL2 = | AC107: back of diaphragm to CL of bridge abutment (m) | AX107: TWfw = | AY107: total web flare width (m)
...

Sheet Outputs
A1: 11. Web Bursting Design
A2: Required Aera of Reinforcement, As.req = | B2: =Calculation!X433 -> 39.870517 | C2: cm2 | E2: References
A3: Provided Aera of Reinforcement, As.prov = | B3: =Calculation!X434 -> 39.741856 | C3: cm2 | E3: AASHTO, 10th
A4: D/C | B4: =B2/B3 -> 1.0032374
A5: 12. Spaling Reinforcing
A6: Required Aera of Reinforcement, As.req = | B6: =Calculation!X443 -> 3.8807922 | C6: cm2
A7: Provided Aera of Reinforcement, As.prov = | B7: =Calculation!X444 -> 3.999992 | C7: cm2
A8: D/C | B8: =B6/B7 -> 0.9702
A9: 13. Concrete Stresses
A10: Concrete Stresses at the Local/General Zone, fci_L.G = | B10: =Calculation!X455 -> 10.041138 | C10: Mpa
A11: Concrete Stresses at the End of Diaphragm, fci_ED = | B11: =Calculation!X464 -> 12.471082 | C11: Mpa
A12: Allowable stress = | B12: =Calculation!X458 -> 13.513724 | C12: Mpa
A13: D/C | B13: =MAX(B10:B11)/B12 -> 0.9228457
A14: 14. Top Slab Analysis
A15: First tie tensile reinforcement requirement:
A16: Required Aera of Reinforcement, As.req = | B16: =Calculation!X588 -> 22.566663 | C16: cm2
A17: Provided Aera of Reinforcement, As.prov = | B17: =Calculation!X589 -> 23.22576 | C17: cm2
A18: D/C | B18: =B16/B17 -> 0.97162215
A19: Second tie tensile reinforcement requirement:
A20: Required Aera of Reinforcement, As.req = | B20: =Calculation!X597 -> 7.3714844 | C20: cm2
A21: Provided Aera of Reinforcement, As.prov = | B21: =Calculation!X598 -> 7.999984 | C21: cm2
A22: D/C | B22: =B20/B21 -> 0.9214374
A23: 15. Bottom Slab Analysis
A24: First tie tensile reinforcement requirement:
A25: Required Aera of Reinforcement, As.req = | B25: =Calculation!X764 -> 68.640838 | C25: in2
A26: Provided Aera of Reinforcement, As.prov = | B26: =Calculation!X765 -> 77.4192 | C26: in2
A27: D/C | B27: =B25/B26 -> 0.88661259

Sheet Template Notes
A1: Template Formatting Notes
A2: 1 | B2: Rows and Columns always 20 pixels
A3: 2 | B3: Use font 9 and type 'Jacobs Chronos' for calcs
A4: 3 | B4: Keep Scale always set to 100% (Page Layout Tab > Scale to Fit > Scale:)
A5: 4 | B5: Top and Bottom Margins set to 0.30"; left and right margins set to 0.25"; Header set to 0.30"; Footer set to 0.00" (Page Layout Tab > Page Setup > Margins Tab)
A6: 5 | B6: Select 'Horiontally' under 'Center on Page' section (Page Layout Tab > Page Setup > Margins Tab)
A7: 6 | B7: Set "$1:$7" in 'Rows to Repeat' (Page Layout > Page Setup > Sheet Tab)
A8: 7 | B8: Excel sets column and row size based on screen pixels. Windows has a setting to scale screen pixels (Display Settings > Scale & Layout > Scale). The amount of space a column or row takes up on the page is directly affected by the windows scale for screen pixels; thus a spreadsheet will print differently if users have different windows pixel scales. Tools have been develped to print with a windows pixel scale of 100%, and the windows pixel scale should be set to this before printing to achieve proper formating.
